<?xml version="1.0" ?>
<!-- =================================================================================== -->
<!-- |    This document was autogenerated by xacro from orne_box.urdf.xacro            | -->
<!-- |    EDITING THIS FILE BY HAND IS NOT RECOMMENDED                                 | -->
<!-- =================================================================================== -->
<robot name="orne_box" xmlns:controller="http://playerstage.sourceforge.net/gazebo/xmlschema/#controller" xmlns:interface="http://playerstage.sourceforge.net/gazebo/xmlschema/#interface">
  <material name="black">
    <color rgba="0.0 0.0 0.0 1.0"/>
  </material>
  <material name="blue">
    <color rgba="0.0 0.0 0.8 1.0"/>
  </material>
  <material name="green">
    <color rgba="0.0 0.8 0.0 1.0"/>
  </material>
  <material name="grey">
    <color rgba="0.2 0.2 0.2 1.0"/>
  </material>
  <material name="orange">
    <color rgba="1.0 0.4235294117647059 0.0392156862745098 1.0"/>
  </material>
  <material name="brown">
    <color rgba="0.8705882352941177 0.8117647058823529 0.7647058823529411 1.0"/>
  </material>
  <material name="red">
    <color rgba="0.8 0.0 0.0 1.0"/>
  </material>
  <material name="white">
    <color rgba="1.0 1.0 1.0 1.0"/>
  </material>
  <!--xacro:arg name="imu_visual"   default="false"/-->
  <gazebo>
    <plugin filename="libgazebo_ros_control.so" name="gazebo_ros_control">
      <robotSimType>icart_mini_gazebo/ICartMiniHWSim</robotSimType>
    </plugin>
  </gazebo>
  <gazebo reference="base_link">
    <material>Gazebo/Orange</material>
  </gazebo>
  <gazebo reference="wheel_left_link">
    <mu1>1.0</mu1>
    <mu2>1.0</mu2>
    <kp>1000000.0</kp>
    <kd>100.0</kd>
    <minDepth>0.001</minDepth>
    <maxVel>1.0</maxVel>
    <material>Gazebo/White</material>
  </gazebo>
  <gazebo reference="wheel_right_link">
    <mu1>1.0</mu1>
    <mu2>1.0</mu2>
    <kp>1000000.0</kp>
    <kd>100.0</kd>
    <minDepth>0.001</minDepth>
    <maxVel>1.0</maxVel>
    <material>Gazebo/White</material>
  </gazebo>
  <gazebo reference="caster_front_link">
    <mu1>0.0</mu1>
    <mu2>0.0</mu2>
    <material>Gazebo/Red</material>
  </gazebo>
  <!--
  <gazebo reference="imu_link">
    <sensor type="imu" name="imu">
      <always_on>true</always_on>
      <visualize>$(arg imu_visual)</visualize>
    </sensor>
    <material>Gazebo/FlatBlack</material>
  </gazebo>
-->
  <!-- hokuyo -->
  <gazebo reference="hokuyo_link">
    <sensor name="head_hokuyo_sensor" type="ray">
      <pose>0 0 0 0 0 0</pose>
      <visualize>true</visualize>
      <update_rate>40</update_rate>
      <ray>
        <scan>
          <horizontal>
            <samples>880</samples>
            <resolution>1</resolution>
            <min_angle>-1.9198621771937625</min_angle>
            <max_angle>1.9198621771937625</max_angle>
          </horizontal>
        </scan>
        <range>
          <min>0.10</min>
          <max>30.0</max>
          <resolution>0.01</resolution>
        </range>
        <noise>
          <type>gaussian</type>
          <!-- Noise parameters based on published spec for Hokuyo laser
               achieving "+-30mm" accuracy at range < 10m.  A mean of 0.0m and
               stddev of 0.01m will put 99.7% of samples within 0.03m of the true
               reading. -->
          <mean>0.0</mean>
          <stddev>0.01</stddev>
        </noise>
      </ray>
      <plugin filename="libgazebo_ros_laser.so" name="gazebo_ros_head_hokuyo_controller">
        <topicName>/scan</topicName>
        <frameName>hokuyo_link</frameName>
      </plugin>
    </sensor>
  </gazebo>
  <link name="base_link">
    <visual>
      <origin rpy="0 0 0" xyz="-0.055 0 0.156"/>
      <geometry>
        <box size="0.53 0.3840 0.2"/>
      </geometry>
      <material name="orange"/>
    </visual>
    <inertial>
      <origin rpy="0 0 0" xyz="0.090 0 0.1715"/>
      <mass value="25.0"/>
      <inertia ixx="1.0" ixy="0.0" ixz="0.0" iyy="1.0" iyz="0.0" izz="1.0"/>
    </inertial>
  </link>
  <joint name="left_wheel_hinge" type="revolute">
    <parent link="base_link"/>
    <child link="wheel_left_link"/>
    <origin rpy="-1.5707963267948966 0 0" xyz="0.0 0.1525 0.075"/>
    <axis xyz="0 0 1"/>
    <limit effort="100" lower="-5000" upper="5000" velocity="100.0"/>
  </joint>
  <link name="wheel_left_link">
    <visual>
      <origin rpy="0 0 0" xyz="0 0 0"/>
      <geometry>
        <cylinder length="0.030" radius="0.075"/>
      </geometry>
      <material name="white"/>
    </visual>
    <collision>
      <origin rpy="0 0 0" xyz="0 0 0"/>
      <geometry>
        <cylinder length="0.030" radius="0.075"/>
      </geometry>
    </collision>
    <inertial>
      <origin xyz="0 0 0"/>
      <mass value="0.2"/>
      <inertia ixx="0.1" ixy="0.0" ixz="0.0" iyy="0.1" iyz="0.0" izz="0.1"/>
    </inertial>
  </link>
  <joint name="right_wheel_hinge" type="revolute">
    <parent link="base_link"/>
    <child link="wheel_right_link"/>
    <origin rpy="-1.5707963267948966 0 0" xyz="0.0 -0.1525 0.075"/>
    <axis xyz="0 0 1"/>
    <limit effort="100" lower="-5000" upper="5000" velocity="100.0"/>
  </joint>
  <link name="wheel_right_link">
    <visual>
      <origin rpy="0 0 0" xyz="0 0 0"/>
      <geometry>
        <cylinder length="0.030" radius="0.075"/>
      </geometry>
      <material name="white"/>
    </visual>
    <collision>
      <origin rpy="0 0 0" xyz="0 0 0"/>
      <geometry>
        <cylinder length="0.030" radius="0.075"/>
      </geometry>
    </collision>
    <inertial>
      <origin xyz="0 0 0"/>
      <mass value="0.2"/>
      <inertia ixx="0.1" ixy="0.0" ixz="0.0" iyy="0.1" iyz="0.0" izz="0.1"/>
    </inertial>
  </link>
  <joint name="caster_front_joint" type="fixed">
    <parent link="base_link"/>
    <child link="caster_front_link"/>
    <origin rpy="0 0 0" xyz="0.21 0 0.050"/>
  </joint>
  <link name="caster_front_link">
    <visual>
      <origin rpy="1.5707963267948966 0 0" xyz="0 0.150 0"/>
      <geometry>
        <cylinder length="0.025" radius="0.050"/>
      </geometry>
      <material name="red"/>
    </visual>
    <visual>
      <origin rpy="1.5707963267948966 0 0" xyz="0 -0.150 0"/>
      <geometry>
        <cylinder length="0.025" radius="0.050"/>
      </geometry>
      <material name="red"/>
    </visual>
    <collision>
      <origin rpy="1.5707963267948966 0 0" xyz="0 0.150 0"/>
      <geometry>
        <cylinder length="0.025" radius="0.050"/>
      </geometry>
    </collision>
    <collision>
      <origin rpy="1.5707963267948966 0 0" xyz="0 -0.150 0"/>
      <geometry>
        <cylinder length="0.025" radius="0.050"/>
      </geometry>
    </collision>
    <inertial>
      <origin xyz="0 0 0"/>
      <mass value="0.2"/>
      <inertia ixx="0.1" ixy="0.0" ixz="0.0" iyy="0.1" iyz="0.0" izz="0.1"/>
    </inertial>
  </link>
  <joint name="caster_back_joint" type="fixed">
    <parent link="base_link"/>
    <child link="caster_back_link"/>
    <origin rpy="0 0 0" xyz="-0.21 0 0.050"/>
  </joint>
  <link name="caster_back_link">
    <visual>
      <origin rpy="1.5707963267948966 0 0" xyz="0 0.150 0"/>
      <geometry>
        <cylinder length="0.025" radius="0.050"/>
      </geometry>
      <material name="red"/>
    </visual>
    <visual>
      <origin rpy="1.5707963267948966 0 0" xyz="0 -0.150 0"/>
      <geometry>
        <cylinder length="0.025" radius="0.050"/>
      </geometry>
      <material name="red"/>
    </visual>
    <collision>
      <origin rpy="1.5707963267948966 0 0" xyz="0 0.150 0"/>
      <geometry>
        <cylinder length="0.025" radius="0.050"/>
      </geometry>
    </collision>
    <collision>
      <origin rpy="1.5707963267948966 0 0" xyz="0 -0.150 0"/>
      <geometry>
        <cylinder length="0.025" radius="0.050"/>
      </geometry>
    </collision>
    <inertial>
      <origin xyz="0 0 0"/>
      <mass value="0.2"/>
      <inertia ixx="0.1" ixy="0.0" ixz="0.0" iyy="0.1" iyz="0.0" izz="0.1"/>
    </inertial>
  </link>
  <!--xacro:include filename="$(find icart_mini_description)/urdf/sensors/imu.urdf.xacro"/-->
  <!-- Setting for imu -->
  <!--
  <xacro:sensor_imu name="imu" parent="base_link" size="0.05 0.05 0.05">
    <origin xyz="0.3 0 0.2445" rpy="0 0 ${-PI/2}"/>
  </xacro:sensor_imu>
  -->
  <joint name="hokuyo_joint" type="fixed">
    <axis xyz="0 1 0"/>
    <origin rpy="0 0 0" xyz="0.13 0 0.5"/>
    <parent link="base_link"/>
    <child link="hokuyo_link"/>
  </joint>
  <link name="hokuyo_link">
    <collision>
      <origin rpy="0 0 0" xyz="0 0 0"/>
      <geometry>
        <box size="0.1 0.1 0.1"/>
      </geometry>
    </collision>
    <visual>
      <origin rpy="0 0 0" xyz="0 0 0"/>
      <geometry>
        <mesh filename="package://icart_mini_description/meshes/hokuyo.dae"/>
      </geometry>
    </visual>
    <inertial>
      <mass value="0.0001"/>
      <origin rpy="0 0 0" xyz="0 0 0"/>
      <inertia ixx="0.0001" ixy="0" ixz="0" iyy="0.0001" iyz="0" izz="0.0001"/>
    </inertial>
  </link>
  <transmission name="tran1">
    <type>transmission_interface/SimpleTransmission</type>
    <joint name="left_wheel_hinge">
      <hardwareInterface>VelocityJointInterface</hardwareInterface>
    </joint>
    <actuator name="left_motor">
      <hardwareInterface>VelocityJointInterface</hardwareInterface>
      <mechanicalReduction>1</mechanicalReduction>
    </actuator>
  </transmission>
  <transmission name="tran2">
    <type>transmission_interface/SimpleTransmission</type>
    <joint name="right_wheel_hinge">
      <hardwareInterface>VelocityJointInterface</hardwareInterface>
    </joint>
    <actuator name="right_motor">
      <hardwareInterface>VelocityJointInterface</hardwareInterface>
      <mechanicalReduction>1</mechanicalReduction>
    </actuator>
  </transmission>
</robot>

