<?xml version="1.0"?>
<robot name="sensor_kinect" 
    xmlns:xacro="http://ros.org/wiki/xacro" 
    xmlns:controller="http://playerstage.sourceforge.net/gazebo/xmlschema/#controller" 
    xmlns:interface="http://playerstage.sourceforge.net/gazebo/xmlschema/#interface" 
    xmlns:sensor="http://playerstage.sourceforge.net/gazebo/xmlschema/#sensor">

    <xacro:include filename="$(find orne_or_description)/urdf/head.gazebo" />

    <xacro:macro name="sensor_kinect" params="name parent *origin">

        <joint name="head_yaw_joint" type="revolute">
            <xacro:insert_block  name="origin"/>
            <parent link="${parent}"/>
            <child link="head_yaw_link"/>
            <axis xyz="0 0 1"/>
            <limit lower="-1.57" upper="1.57" effort="0.5" velocity="6.0"/>
            <friction friction="0.01" />
            <dynamics damping="0.4" />
        </joint>

        <link name="head_yaw_link">
            <inertial>
                <mass value="0.107" />
                <origin xyz="0.053 0.000 0.000" />
                <inertia ixx="0.000024" ixy="0.0" ixz="0.0" iyy="0.000354" iyz="0.0" izz="0.000355" />
            </inertial>
            <visual>
                <geometry>
                    <mesh filename="package://orne_or_description/meshes/head_yaw_link.stl"/>
                </geometry>
            </visual>
            <collision>
                <geometry>
                    <box size="0.0330 0.0320 0.0320"/>
                </geometry>
            </collision>
        </link>

        <joint name="head_pitch_joint" type="revolute">
            <origin xyz="0.0713 0 0"/>
            <parent link="head_yaw_link"/>
            <child link="head_link"/>
            <axis xyz="0 1 0"/>
            <limit lower="-1.57" upper="1.57" effort="0.5" velocity="6.0"/>
        </joint>

        <link name="head_link">
            <inertial>
                <mass value="0.611" />
                <origin xyz="-0.005 0.000 0.045" />
                <inertia ixx="0.004445" ixy="0.0" ixz="0.0" iyy="0.001536" iyz="0.0" izz="0.003296" />
            </inertial>
            <visual>
                <origin xyz=" 0 0 0 " rpy="0 0 0" />
                <geometry>
                    <mesh filename="package://orne_or_description/meshes/head_link.stl"/>
                </geometry>
            </visual>
            <collision>
                <origin xyz="0.0 0.0 0.0" rpy="0 0 0" />
                <geometry>
                    <box size="0.0330 0.0320 0.0320"/>
                </geometry>
            </collision>
        </link>

        <joint name="camera_joint" type="fixed">
            <origin xyz="0.03 0 0" rpy="0 0 0"/>
            <parent link="head_link"/>
            <child link="camera_link"/>
        </joint>

        <link name="camera_link">
            <inertial>
                <mass value="0.01" />
                <origin xyz="0 0 0" />
                <inertia ixx="0.0001" ixy="0.0" ixz="0.0" iyy="0.0001" iyz="0.0" izz="0.0001" />
            </inertial>
        </link>
        <transmission name="tran3">
            <type>transmission_interface/SimpleTransmission</type>
            <joint name="head_yaw_joint">
                <hardwareInterface>PositionJointInterface</hardwareInterface>
            </joint>   
            <actuator name="head_yaw_motor">
                <hardwareInterface>PositionJointInterface</hardwareInterface>
                <mechanicalReduction>1</mechanicalReduction>
            </actuator>
        </transmission>

        <transmission name="tran4">
            <type>transmission_interface/SimpleTransmission</type>
            <joint name="head_pitch_joint">
                <hardwareInterface>PositionJointInterface</hardwareInterface>
            </joint>  
            <actuator name="head_pitch_motor">
                <hardwareInterface>PositionJointInterface</hardwareInterface>
                <mechanicalReduction>1</mechanicalReduction>
            </actuator>
        </transmission>

    </xacro:macro>
</robot>
